<sdf version='1.7'>
  <world name='default'>
    <light name='sun' type='directional'>
      <cast_shadows>1</cast_shadows>
      <pose>0 0 10 0 -0 0</pose>
      <diffuse>0.8 0.8 0.8 1</diffuse>
      <specular>0.2 0.2 0.2 1</specular>
      <attenuation>
        <range>1000</range>
        <constant>0.9</constant>
        <linear>0.01</linear>
        <quadratic>0.001</quadratic>
      </attenuation>
      <direction>-0.5 0.1 -0.9</direction>
      <spot>
        <inner_angle>0</inner_angle>
        <outer_angle>0</outer_angle>
        <falloff>0</falloff>
      </spot>
    </light>
    <model name='ground_plane'>
      <static>1</static>
      <link name='link'>
        <collision name='collision'>
          <geometry>
            <plane>
              <normal>0 0 1</normal>
              <size>100 100</size>
            </plane>
          </geometry>
          <surface>
            <friction>
              <ode>
                <mu>100</mu>
                <mu2>50</mu2>
              </ode>
              <torsional>
                <ode/>
              </torsional>
            </friction>
            <contact>
              <ode/>
            </contact>
            <bounce/>
          </surface>
          <max_contacts>10</max_contacts>
        </collision>
        <visual name='visual'>
          <cast_shadows>0</cast_shadows>
          <geometry>
            <plane>
              <normal>0 0 1</normal>
              <size>100 100</size>
            </plane>
          </geometry>
          <material>
            <script>
              <uri>file://media/materials/scripts/gazebo.material</uri>
              <name>Gazebo/Grey</name>
            </script>
          </material>
        </visual>
        <self_collide>0</self_collide>
        <enable_wind>0</enable_wind>
        <kinematic>0</kinematic>
      </link>
    </model>
    <gravity>0 0 -9.8</gravity>
    <magnetic_field>6e-06 2.3e-05 -4.2e-05</magnetic_field>
    <atmosphere type='adiabatic'/>
    <physics type='ode'>
      <max_step_size>0.001</max_step_size>
      <real_time_factor>1</real_time_factor>
      <real_time_update_rate>1000</real_time_update_rate>
    </physics>
    <scene>
      <ambient>0.4 0.4 0.4 1</ambient>
      <background>0.7 0.7 0.7 1</background>
      <shadows>1</shadows>
    </scene>
    <wind/>
    <spherical_coordinates>
      <surface_model>EARTH_WGS84</surface_model>
      <latitude_deg>0</latitude_deg>
      <longitude_deg>0</longitude_deg>
      <elevation>0</elevation>
      <heading_deg>0</heading_deg>
    </spherical_coordinates>
    <model name='h2mare_offshore'>
      <link name='link_0'>
        <inertial>
          <mass>1</mass>
          <inertia>
            <ixx>0.166667</ixx>
            <ixy>0</ixy>
            <ixz>0</ixz>
            <iyy>0.166667</iyy>
            <iyz>0</iyz>
            <izz>0.166667</izz>
          </inertia>
          <pose>0 0 0 0 -0 0</pose>
        </inertial>
        <pose>-8.44837 0.478393 -0.328859 0 -0 0</pose>
        <visual name='visual'>
          <pose>0 0 0 0 -0 0</pose>
          <geometry>
            <mesh>
              <uri>/home/eiche/Desktop/h2mare_visual.obj</uri>
              <scale>1 1 1</scale>
            </mesh>
          </geometry>
          <material>
            <lighting>1</lighting>
            <script>
              <uri>file://media/materials/scripts/gazebo.material</uri>
              <name>Gazebo/Grey</name>
            </script>
            <shader type='pixel'/>
            <emissive>0 0 0 1</emissive>
          </material>
          <transparency>0</transparency>
          <cast_shadows>1</cast_shadows>
        </visual>
        <collision name='collision'>
          <laser_retro>0</laser_retro>
          <max_contacts>10</max_contacts>
          <pose>0 0 0 0 -0 0</pose>
          <geometry>
            <mesh>
              <uri>/home/eiche/Desktop/h2mare_visual.obj</uri>
              <scale>1 1 1</scale>
            </mesh>
          </geometry>
          <surface>
            <friction>
              <ode>
                <mu>1</mu>
                <mu2>1</mu2>
                <fdir1>0 0 0</fdir1>
                <slip1>0</slip1>
                <slip2>0</slip2>
              </ode>
              <torsional>
                <coefficient>1</coefficient>
                <patch_radius>0</patch_radius>
                <surface_radius>0</surface_radius>
                <use_patch_radius>1</use_patch_radius>
                <ode>
                  <slip>0</slip>
                </ode>
              </torsional>
            </friction>
            <bounce>
              <restitution_coefficient>0</restitution_coefficient>
              <threshold>1e+06</threshold>
            </bounce>
            <contact>
              <collide_without_contact>0</collide_without_contact>
              <collide_without_contact_bitmask>1</collide_without_contact_bitmask>
              <collide_bitmask>1</collide_bitmask>
              <ode>
                <soft_cfm>0</soft_cfm>
                <soft_erp>0.2</soft_erp>
                <kp>1e+13</kp>
                <kd>1</kd>
                <max_vel>0.01</max_vel>
                <min_depth>0</min_depth>
              </ode>
              <bullet>
                <split_impulse>1</split_impulse>
                <split_impulse_penetration_threshold>-0.01</split_impulse_penetration_threshold>
                <soft_cfm>0</soft_cfm>
                <soft_erp>0.2</soft_erp>
                <kp>1e+13</kp>
                <kd>1</kd>
              </bullet>
            </contact>
          </surface>
        </collision>
        <self_collide>0</self_collide>
        <enable_wind>0</enable_wind>
        <kinematic>0</kinematic>
      </link>
      <model name='wheel_valve'>
        <link name='handle'>
          <pose>0 0 0.1 0 -0 1.57</pose>
          <inertial>
            <mass>7.9917</mass>
            <pose>0.05 0 0 0 -0 0</pose>
            <inertia>
              <ixx>0.0689</ixx>
              <ixy>0</ixy>
              <ixz>0</ixz>
              <iyy>0.0353</iyy>
              <iyz>0</iyz>
              <izz>0.0353</izz>
            </inertia>
          </inertial>
          <collision name='collision'>
            <geometry>
              <mesh>
                <uri>model://drc_practice_wheel_valve/meshes/valve_wheel.dae</uri>
              </mesh>
            </geometry>
            <surface>
              <bounce>
                <restitution_coefficient>0.01</restitution_coefficient>
                <threshold>5</threshold>
              </bounce>
              <friction>
                <ode>
                  <mu>5</mu>
                  <mu2>5</mu2>
                </ode>
                <torsional>
                  <ode/>
                </torsional>
              </friction>
              <contact>
                <ode>
                  <soft_cfm>0.01</soft_cfm>
                  <kp>1e+06</kp>
                  <kd>100000</kd>
                  <max_vel>0.01</max_vel>
                  <min_depth>0.001</min_depth>
                </ode>
              </contact>
            </surface>
            <max_contacts>10</max_contacts>
          </collision>
          <visual name='visual'>
            <geometry>
              <mesh>
                <uri>model://drc_practice_wheel_valve/meshes/valve_wheel.dae</uri>
              </mesh>
            </geometry>
          </visual>
          <self_collide>0</self_collide>
          <enable_wind>0</enable_wind>
          <kinematic>0</kinematic>
        </link>
        <joint name='joint' type='revolute'>
          <parent>world</parent>
          <child>handle</child>
          <axis>
            <xyz expressed_in='__model__'>0 1 0</xyz>
            <limit>
              <lower>-12.56</lower>
              <upper>12.56</upper>
            </limit>
            <dynamics>
              <damping>1000</damping>
              <friction>100</friction>
              <spring_reference>0</spring_reference>
              <spring_stiffness>0</spring_stiffness>
            </dynamics>
          </axis>
          <physics>
            <ode>
              <implicit_spring_damper>1</implicit_spring_damper>
              <limit>
                <cfm>0</cfm>
                <erp>0.2</erp>
              </limit>
            </ode>
          </physics>
        </joint>
        <pose>4.55943 -3.31572 -0.067657 0 -0 1.59611</pose>
      </model>
      <model name='wheel_valve_large'>
        <link name='handle'>
          <pose>0 0.031 0 0 -0 0</pose>
          <inertial>
            <mass>7.8219</mass>
            <pose>0 0.0615 0 0 -0 0</pose>
            <inertia>
              <ixx>0.0695</ixx>
              <ixy>0</ixy>
              <ixz>0</ixz>
              <iyy>0.1349</iyy>
              <iyz>0</iyz>
              <izz>0.0695</izz>
            </inertia>
          </inertial>
          <collision name='collision'>
            <geometry>
              <mesh>
                <uri>model://drc_practice_wheel_valve_large/meshes/wheel_valve_large.dae</uri>
              </mesh>
            </geometry>
            <surface>
              <friction>
                <ode>
                  <mu>1</mu>
                  <mu2>1</mu2>
                </ode>
                <torsional>
                  <ode/>
                </torsional>
              </friction>
              <contact>
                <ode>
                  <kp>1e+06</kp>
                  <kd>100</kd>
                  <max_vel>0.01</max_vel>
                  <min_depth>0.001</min_depth>
                </ode>
              </contact>
              <bounce/>
            </surface>
            <max_contacts>10</max_contacts>
          </collision>
          <visual name='visual'>
            <geometry>
              <mesh>
                <uri>model://drc_practice_wheel_valve_large/meshes/wheel_valve_large.dae</uri>
              </mesh>
            </geometry>
          </visual>
          <self_collide>0</self_collide>
          <enable_wind>0</enable_wind>
          <kinematic>0</kinematic>
        </link>
        <joint name='joint' type='revolute'>
          <parent>world</parent>
          <child>handle</child>
          <axis>
            <xyz>0 1 0</xyz>
            <limit>
              <lower>-12.56</lower>
              <upper>12.56</upper>
            </limit>
            <dynamics>
              <damping>0.1</damping>
              <friction>0.1</friction>
              <spring_reference>0</spring_reference>
              <spring_stiffness>0</spring_stiffness>
            </dynamics>
          </axis>
          <physics>
            <ode>
              <implicit_spring_damper>1</implicit_spring_damper>
              <limit>
                <cfm>0</cfm>
                <erp>0.2</erp>
              </limit>
            </ode>
          </physics>
        </joint>
        <pose>-0.952348 5.26131 0.192787 0 -0 -3.12082</pose>
      </model>
      <model name='wheel_valve_large_0'>
        <link name='handle'>
          <pose>0 0.031 0 0 -0 0</pose>
          <inertial>
            <mass>7.8219</mass>
            <pose>0 0.0615 0 0 -0 0</pose>
            <inertia>
              <ixx>0.0695</ixx>
              <ixy>0</ixy>
              <ixz>0</ixz>
              <iyy>0.1349</iyy>
              <iyz>0</iyz>
              <izz>0.0695</izz>
            </inertia>
          </inertial>
          <collision name='collision'>
            <geometry>
              <mesh>
                <uri>model://drc_practice_wheel_valve_large/meshes/wheel_valve_large.dae</uri>
              </mesh>
            </geometry>
            <surface>
              <friction>
                <ode>
                  <mu>1</mu>
                  <mu2>1</mu2>
                </ode>
                <torsional>
                  <ode/>
                </torsional>
              </friction>
              <contact>
                <ode>
                  <kp>1e+06</kp>
                  <kd>100</kd>
                  <max_vel>0.01</max_vel>
                  <min_depth>0.001</min_depth>
                </ode>
              </contact>
              <bounce/>
            </surface>
            <max_contacts>10</max_contacts>
          </collision>
          <visual name='visual'>
            <geometry>
              <mesh>
                <uri>model://drc_practice_wheel_valve_large/meshes/wheel_valve_large.dae</uri>
              </mesh>
            </geometry>
          </visual>
          <self_collide>0</self_collide>
          <enable_wind>0</enable_wind>
          <kinematic>0</kinematic>
        </link>
        <joint name='joint' type='revolute'>
          <parent>world</parent>
          <child>handle</child>
          <axis>
            <xyz>0 1 0</xyz>
            <limit>
              <lower>-12.56</lower>
              <upper>12.56</upper>
            </limit>
            <dynamics>
              <damping>0.1</damping>
              <friction>0.1</friction>
              <spring_reference>0</spring_reference>
              <spring_stiffness>0</spring_stiffness>
            </dynamics>
          </axis>
          <physics>
            <ode>
              <implicit_spring_damper>1</implicit_spring_damper>
              <limit>
                <cfm>0</cfm>
                <erp>0.2</erp>
              </limit>
            </ode>
          </physics>
        </joint>
        <pose>4.84128 -2.42397 0.20373 0 -0 1.56549</pose>
      </model>
      <joint name='link_0_JOINT_0' type='revolute'>
        <parent>link_0</parent>
        <child>wheel_valve_large::handle</child>
        <pose>0 0 0 0 -0 0</pose>
        <axis>
          <xyz>0 1 0</xyz>
          <limit>
            <lower>-1.79769e+308</lower>
            <upper>1.79769e+308</upper>
            <effort>-1</effort>
            <velocity>-1</velocity>
          </limit>
          <dynamics>
            <spring_reference>0</spring_reference>
            <spring_stiffness>0</spring_stiffness>
            <damping>0</damping>
          </dynamics>
        </axis>
        <physics>
          <ode>
            <limit>
              <cfm>0</cfm>
              <erp>0.2</erp>
            </limit>
            <suspension>
              <cfm>0</cfm>
              <erp>0.2</erp>
            </suspension>
          </ode>
        </physics>
      </joint>
      <joint name='link_0_JOINT_1' type='revolute'>
        <parent>link_0</parent>
        <child>wheel_valve::handle</child>
        <pose>0 0 0 0 -0 0</pose>
        <axis>
          <xyz>1 0 0</xyz>
          <limit>
            <lower>-1.79769e+308</lower>
            <upper>1.79769e+308</upper>
            <effort>-1</effort>
            <velocity>-1</velocity>
          </limit>
          <dynamics>
            <spring_reference>0</spring_reference>
            <spring_stiffness>0</spring_stiffness>
            <damping>0</damping>
          </dynamics>
        </axis>
        <physics>
          <ode>
            <limit>
              <cfm>0</cfm>
              <erp>0.2</erp>
            </limit>
            <suspension>
              <cfm>0</cfm>
              <erp>0.2</erp>
            </suspension>
          </ode>
        </physics>
      </joint>
      <joint name='link_0_JOINT_2' type='revolute'>
        <parent>link_0</parent>
        <child>wheel_valve_large_0::handle</child>
        <pose>0 0 0 0 -0 0</pose>
        <axis>
          <xyz>0 1 0</xyz>
          <limit>
            <lower>-1.79769e+308</lower>
            <upper>1.79769e+308</upper>
            <effort>-1</effort>
            <velocity>-1</velocity>
          </limit>
          <dynamics>
            <spring_reference>0</spring_reference>
            <spring_stiffness>0</spring_stiffness>
            <damping>0</damping>
          </dynamics>
        </axis>
        <physics>
          <ode>
            <limit>
              <cfm>0</cfm>
              <erp>0.2</erp>
            </limit>
            <suspension>
              <cfm>0</cfm>
              <erp>0.2</erp>
            </suspension>
          </ode>
        </physics>
      </joint>
      <static>0</static>
      <allow_auto_disable>1</allow_auto_disable>
      <pose>6.52419 -2.40252 0.328859 0 -0 0</pose>
    </model>
    <state world_name='default'>
      <sim_time>28 692000000</sim_time>
      <real_time>28 845719332</real_time>
      <wall_time>1774479512 365630703</wall_time>
      <iterations>28692</iterations>
      <model name='ground_plane'>
        <pose>0 0 0 0 -0 0</pose>
        <scale>1 1 1</scale>
        <link name='link'>
          <pose>0 0 0 0 -0 0</pose>
          <velocity>0 0 0 0 -0 0</velocity>
          <acceleration>0 0 0 0 -0 0</acceleration>
          <wrench>0 0 0 0 -0 0</wrench>
        </link>
      </model>
      <model name='h2mare_offshore'>
        <pose>6.52419 -2.40252 0.328859 0 -0 0</pose>
        <scale>1 1 1</scale>
        <link name='link_0'>
          <pose>-1.92418 -1.92413 0 0 -0 0</pose>
          <velocity>0 0 0 0 -0 0</velocity>
          <acceleration>0 0 0 0 -0 0</acceleration>
          <wrench>0 0 0 0 -0 0</wrench>
        </link>
        <model name='wheel_valve'>
          <pose>11.0836 -5.71824 0.261202 0 -0 1.59611</pose>
          <scale>1 1 1</scale>
          <link name='handle'>
            <pose>11.0836 -5.71824 0.361202 0 -0 -3.11707</pose>
            <velocity>0 0 0 0 -0 0</velocity>
            <acceleration>0 0 0 0 -0 0</acceleration>
            <wrench>0 0 0 0 -0 0</wrench>
          </link>
        </model>
        <model name='wheel_valve_large'>
          <pose>5.57184 2.85879 0.521646 0 0 -3.12082</pose>
          <scale>1 1 1</scale>
          <link name='handle'>
            <pose>5.57249 2.8278 0.521646 0 0 -3.12082</pose>
            <velocity>0 0 0 0 -0 0</velocity>
            <acceleration>0 0 0 0 -0 0</acceleration>
            <wrench>0 0 0 0 -0 0</wrench>
          </link>
        </model>
        <model name='wheel_valve_large_0'>
          <pose>11.3655 -4.82649 0.532589 0 -0 1.56549</pose>
          <scale>1 1 1</scale>
          <link name='handle'>
            <pose>11.3345 -4.82633 0.532589 0 -0 1.56549</pose>
            <velocity>0 0 0 0 -0 0</velocity>
            <acceleration>0 0 0 0 -0 0</acceleration>
            <wrench>0 0 0 0 -0 0</wrench>
          </link>
        </model>
      </model>
      <light name='sun'>
        <pose>0 0 10 0 -0 0</pose>
      </light>
    </state>
    <gui fullscreen='0'>
      <camera name='user_camera'>
        <pose>6.92695 -5.87881 4.04028 0 0.701797 -0.230981</pose>
        <view_controller>orbit</view_controller>
        <projection_type>perspective</projection_type>
      </camera>
    </gui>
  </world>
</sdf>
